---
layout: post
title: "上周的记录：错误捕捉"
date: 2020-02-16 17:00:00 +0800
categories: weekly
---

## 思考

### 是否捕捉这个的错误？

程序中的错误是可以主动捕捉和处理的，以避免程序中止。但并非所有的错误都要捕捉。这取决于错误是内部处理还是外部处理。如果内部处理，则会捕捉；如果是外部处理，则不会捕捉，任其抛出。这里的外部指的是当前模块的高层执行者，既可以是高层代码，也可以是开发者。

例如一个数据查询模块已经做了捕捉错误的准备，则数据库连接函数可以大胆地将连接数据库的错误抛出，将该问题交给外部处理。数据查询模块会记录相关错误，然后尝试重新连接，或者取消任务然后发送邮件告知开发者，从而将该问题内部处理。

例如一个供开发者调用的接口函数，如果存在内部无法解决的开发者的输入错误，那么应该抛出错误，因为只有“开发者”这个外部存在可以解决这个问题。

但如果是用户在使用一个软件使用了错误的输入，那么就不直接能抛出错误，而应该对错误进行捕捉，然后以用户可理解的形式告知。

程序的错误处理就像是社会组织中的问题处理。如果一个问题是底层可以内部处理的，则不必要抛给上层。但如果上层指明相关问题由自己处理，则底层可以放心交给上层。

内部处理可以减少高层的复杂度，但是模块自身的复杂度会增加。反过来，外部处理可以降低模块自身的复杂度，但是会增加高层的复杂度。所以这是一个底层和高层在复杂度上的博弈。

至于错误的日志，其主要是方便开发者的Debug。在捕捉错误并打算以邮件等形式通知开发者时，应该记录相关错误日志。而对于内部处理的错误，则可以根据Debug是否会涉及到而选择性记录。

内部处理的形式通常包括：

- 采用备选逻辑，例如另一种实现，重运行
- 通知外部来解决
- 忽略

捕捉错误、进行内部处理的Python参考代码

```python
# Solve it yourself

def func():
    try:
        done()
    except IOError:
        doSomethingElse()
```

抛出错误、交给外部处理的Python参考代码
```python
# Ask for help

def func1():
    result = done()
    if result != expected:
        raise SomeError("result != expected")

# or

def func2():
    result = done()
    assert result != expected, SomeError("result != expected")

```
